Workbook

Sheet Ringkasan
B2: Simulasi Baseline Pot Produksi Fixed per Kelas Event
B4: Isi workbook:
B5: 1. Tarif_Plan | C5: Tabel tarif fixed per kelas event (Lantai, PM, VJ, Pot Produksi, Total) — EDIT DI SINI kalau ada perubahan angka/kelas.
B6: 2. Pembagian_Pot_PM | C6: Pembagian Pot PM (Lead/Support) berdasarkan jumlah PM yang terlibat — terpisah total dari Pot Produksi.
B7: 3. Simulasi_Rekap_Produksi | C7: Contoh nyata pakai data Juli 2026 (26 event, 158 baris) — hitung otomatis nominal per anak dari poin & kelas event.
B9: Konsep Perhitungan:
B10: • | C10: Pot Produksi itu FIXED per kelas event (bukan dihitung dari poin x rate) — jadi total biaya produksi 1 event TIDAK PERNAH melebihi pot kelasnya.
B11: • | C11: Nominal per Anak = (Poin Anak Itu / Total Poin Semua Anak di Event Itu) x Pot Produksi Kelas Itu.
B12: • | C12: Pot PM (Lead/Support) dihitung TERPISAH dari Pot Produksi, berdasarkan tabel Pembagian Pot PM (fixed sesuai jumlah PM, tidak terkait poin).
B13: • | C13: Pembulatan: baris dengan poin terakhir di tiap event otomatis menyerap selisih pembulatan, supaya total per event selalu PAS dengan Pot Produksi (tidak lebih/kurang karena pembulatan desimal).
B14: • | C14: Event dengan Total Poin = 0 (belum ada satupun poin tercatat) ditandai 'PERLU KEPUTUSAN MANUAL' — nominal tidak otomatis dibagi karena tidak ada dasar kontribusi.
B16: Catatan:
B17: • | C17: Kolom 'Kelas Event' di sheet Simulasi_Rekap_Produksi masih CONTOH/PLACEHOLDER (belum sesuai kelas asli tiap event) — silakan edit sesuai kelas yang benar, nominal akan otomatis re-kalkulasi.
B18: • | C18: Semua angka di Tarif_Plan_E & Pembagian_Pot_PM juga masih mengikuti draft yang dikirim — silakan diedit langsung kalau ada revisi dari direksi.

Sheet Tarif_Plan
B2: Tarif Plan E per Event
B4: Kelas | C4: Lantai | D4: Turun Kelas di Bawah | E4: PM | F4: VJ | G4: Pot Produksi | H4: Total | I4: % Lantai
B5: S · 1 PM | C5: 75000000 | D5: 67500000 | E5: 2500000 | F5: 350000 | G5: 3500000 | H5: =E5+F5+G5 -> 6350000 | I5: =H5/C5 -> 0.084666667
B6: S · 2 PM | E6: 2500000 | F6: 350000 | G6: 4000000 | H6: =E6+F6+G6 -> 6850000 | I6: =H6/C$5 -> 0.091333333
B7: S · 3 PM | E7: 3000000 | F7: 350000 | G7: 4500000 | H7: =E7+F7+G7 -> 7850000 | I7: =H7/C$5 -> 0.10466667
B8: A | C8: 40000000 | D8: 36000000 | E8: 1250000 | F8: 200000 | G8: 2000000 | H8: =E8+F8+G8 -> 3450000 | I8: =H8/C8 -> 0.08625
B9: B | C9: 25000000 | D9: 22500000 | E9: 1000000 | F9: 125000 | G9: 1000000 | H9: =E9+F9+G9 -> 2125000 | I9: =H9/C9 -> 0.085
B10: C | C10: 15000000 | D10: - kelas dasar | E10: 250000 | F10: 100000 | G10: 500000 | H10: =E10+F10+G10 -> 850000 | I10: =H10/C10 -> 0.056666667
B13: Catatan: 'Turun Kelas di Bawah' = nominal Lantai kalau event ini diturunkan 1 tingkat kelas (referensi negosiasi, tidak dipakai dalam kalkulasi pot produksi).

Sheet Pembagian_Pot_PM
B2: Pembagian Pot PM
B3: Terpisah total dari Pot Produksi — fixed sesuai jumlah PM, tidak terkait poin produksi
B5: Konfigurasi | C5: Split | D5: Lead | E5: Support 1 | F5: Support 2
B6: 1 PM (solo) | C6: 100 | D6: 2500000
B7: 2 PM | C7: 70/30 | D7: 1750000 | E7: 750000
B8: 3 PM | C8: 50/25/25 | D8: 1500000 | E8: 750000 | F8: 750000
B11: Catatan: PM (2.500.000 / 1.750.000+750.000 / dst di tabel Tarif_Plan kolom 'PM') adalah total pot PM per event; tabel ini cuma acuan Lead vs Support-nya berapa masing-masing.

Sheet Simulasi_Rekap_Produksi
B2: Simulasi Rekap Produksi — Data Juli 2026 (26 event, 158 baris)
B5: Nama Event | C5: Nama Karyawan | D5: Jabatan | E5: Poin | F5: Total Poin Event | G5: Kelas Event | H5: Pot Produksi (Kelas) | I5: % Kontribusi | J5: Nominal Dasar | K5: Baris Terakhir? | L5: Total Nominal Dasar (Event) | M5: Selisih Pembulatan | N5: Nominal Final | O5: Status
B6: The Wedding of Hariyanto & Ananda Priscilla | C6: Ariya Putra Sundava | D6: Jumpback | E6: 0 | F6: =SUMIF($B$6:$B$162,B6,$E$6:$E$162) -> 30 | G6: B | H6: =IFERROR(VLOOKUP(G6,Tarif_Plan!$B$5:$G$10,6,FALSE()),"Kelas tdk ditemukan") -> 1000000 | I6: =IF(F6=0,0,E6/F6) -> 0 | J6: =ROUND(I6*H6,0) -> 0 | K6: =IF(COUNTIF($B$6:B6,B6)=COUNTIF($B$6:$B$162,B6),1,0) -> 0 | L6: =SUMIF($B$6:$B$162,B6,$J$6:$J$162) -> 1000000 | M6: =H6-L6 -> 0 | N6: =IF(F6=0,0,J6+IF(K6=1,M6,0)) -> 0 | O6: =IF(F6=0,"POIN 0 - PERLU KEPUTUSAN MANUAL","OK") -> OK
B7: The Wedding of Hariyanto & Ananda Priscilla | C7: Giantoro Susilo | D7: Asset | E7: 1 | F7: =SUMIF($B$6:$B$162,B7,$E$6:$E$162) -> 30 | G7: B | H7: =IFERROR(VLOOKUP(G7,Tarif_Plan!$B$5:$G$10,6,FALSE()),"Kelas tdk ditemukan") -> 1000000 | I7: =IF(F7=0,0,E7/F7) -> 0.033333333 | J7: =ROUND(I7*H7,0) -> 33333 | K7: =IF(COUNTIF($B$6:B7,B7)=COUNTIF($B$6:$B$162,B7),1,0) -> 0 | L7: =SUMIF($B$6:$B$162,B7,$J$6:$J$162) -> 1000000 | M7: =H7-L7 -> 0 | N7: =IF(F7=0,0,J7+IF(K7=1,M7,0)) -> 33333 | O7: =IF(F7=0,"POIN 0 - PERLU KEPUTUSAN MANUAL","OK") -> OK
B8: The Wedding of Hariyanto & Ananda Priscilla | C8: Muhammad Kanza Eka Ghifari | D8: Compose | E8: 5 | F8: =SUMIF($B$6:$B$162,B8,$E$6:$E$162) -> 30 | G8: B | H8: =IFERROR(VLOOKUP(G8,Tarif_Plan!$B$5:$G$10,6,FALSE()),"Kelas tdk ditemukan") -> 1000000 | I8: =IF(F8=0,0,E8/F8) -> 0.16666667 | J8: =ROUND(I8*H8,0) -> 166667 | K8: =IF(COUNTIF($B$6:B8,B8)=COUNTIF($B$6:$B$162,B8),1,0) -> 0 | L8: =SUMIF($B$6:$B$162,B8,$J$6:$J$162) -> 1000000 | M8: =H8-L8 -> 0 | N8: =IF(F8=0,0,J8+IF(K8=1,M8,0)) -> 166667 | O8: =IF(F8=0,"POIN 0 - PERLU KEPUTUSAN MANUAL","OK") -> OK
B9: The Wedding of Hariyanto & Ananda Priscilla | C9: Ardian Firmansyah | D9: Compose | E9: 5 | F9: =SUMIF($B$6:$B$162,B9,$E$6:$E$162) -> 30 | G9: B | H9: =IFERROR(VLOOKUP(G9,Tarif_Plan!$B$5:$G$10,6,FALSE()),"Kelas tdk ditemukan") -> 1000000 | I9: =IF(F9=0,0,E9/F9) -> 0.16666667 | J9: =ROUND(I9*H9,0) -> 166667 | K9: =IF(COUNTIF($B$6:B9,B9)=COUNTIF($B$6:$B$162,B9),1,0) -> 0 | L9: =SUMIF($B$6:$B$162,B9,$J$6:$J$162) -> 1000000 | M9: =H9-L9 -> 0 | N9: =IF(F9=0,0,J9+IF(K9=1,M9,0)) -> 166667 | O9: =IF(F9=0,"POIN 0 - PERLU KEPUTUSAN MANUAL","OK") -> OK
B10: The Wedding of Hariyanto & Ananda Priscilla | C10: Arif Cendekiawan | D10: Generalist (All in One) | E10: 5 | F10: =SUMIF($B$6:$B$162,B10,$E$6:$E$162) -> 30 | G10: B | H10: =IFERROR(VLOOKUP(G10,Tarif_Plan!$B$5:$G$10,6,FALSE()),"Kelas tdk ditemukan") -> 1000000 | I10: =IF(F10=0,0,E10/F10) -> 0.16666667 | J10: =ROUND(I10*H10,0) -> 166667 | K10: =IF(COUNTIF($B$6:B10,B10)=COUNTIF($B$6:$B$162,B10),1,0) -> 0 | L10: =SUMIF($B$6:$B$162,B10,$J$6:$J$162) -> 1000000 | M10: =H10-L10 -> 0 | N10: =IF(F10=0,0,J10+IF(K10=1,M10,0)) -> 166667 | O10: =IF(F10=0,"POIN 0 - PERLU KEPUTUSAN MANUAL","OK") -> OK
B11: The Wedding of Hariyanto & Ananda Priscilla | C11: Hafid Asari | D11: Animator | E11: 7 | F11: =SUMIF($B$6:$B$162,B11,$E$6:$E$162) -> 30 | G11: B | H11: =IFERROR(VLOOKUP(G11,Tarif_Plan!$B$5:$G$10,6,FALSE()),"Kelas tdk ditemukan") -> 1000000 | I11: =IF(F11=0,0,E11/F11) -> 0.23333333 | J11: =ROUND(I11*H11,0) -> 233333 | K11: =IF(COUNTIF($B$6:B11,B11)=COUNTIF($B$6:$B$162,B11),1,0) -> 0 | L11: =SUMIF($B$6:$B$162,B11,$J$6:$J$162) -> 1000000 | M11: =H11-L11 -> 0 | N11: =IF(F11=0,0,J11+IF(K11=1,M11,0)) -> 233333 | O11: =IF(F11=0,"POIN 0 - PERLU KEPUTUSAN MANUAL","OK") -> OK
B12: The Wedding of Hariyanto & Ananda Priscilla | C12: Nur Laily Ida Yagshya | D12: Animator | E12: 6 | F12: =SUMIF($B$6:$B$162,B12,$E$6:$E$162) -> 30 | G12: B | H12: =IFERROR(VLOOKUP(G12,Tarif_Plan!$B$5:$G$10,6,FALSE()),"Kelas tdk ditemukan") -> 1000000 | I12: =IF(F12=0,0,E12/F12) -> 0.2 | J12: =ROUND(I12*H12,0) -> 200000 | K12: =IF(COUNTIF($B$6:B12,B12)=COUNTIF($B$6:$B$162,B12),1,0) -> 0 | L12: =SUMIF($B$6:$B$162,B12,$J$6:$J$162) -> 1000000 | M12: =H12-L12 -> 0 | N12: =IF(F12=0,0,J12+IF(K12=1,M12,0)) -> 200000 | O12: =IF(F12=0,"POIN 0 - PERLU KEPUTUSAN MANUAL","OK") -> OK
B13: The Wedding of Hariyanto & Ananda Priscilla | C13: Ridwan Gavyn Ramadhan | D13: Animator | E13: 1 | F13: =SUMIF($B$6:$B$162,B13,$E$6:$E$162) -> 30 | G13: B | H13: =IFERROR(VLOOKUP(G13,Tarif_Plan!$B$5:$G$10,6,FALSE()),"Kelas tdk ditemukan") -> 1000000 | I13: =IF(F13=0,0,E13/F13) -> 0.033333333 | J13: =ROUND(I13*H13,0) -> 33333 | K13: =IF(COUNTIF($B$6:B13,B13)=COUNTIF($B$6:$B$162,B13),1,0) -> 0 | L13: =SUMIF($B$6:$B$162,B13,$J$6:$J$162) -> 1000000 | M13: =H13-L13 -> 0 | N13: =IF(F13=0,0,J13+IF(K13=1,M13,0)) -> 33333 | O13: =IF(F13=0,"POIN 0 - PERLU KEPUTUSAN MANUAL","OK") -> OK
B14: The Wedding of Hariyanto & Ananda Priscilla | C14: Ariya Putra Sundava | D14: Jumpback | E14: 0 | F14: =SUMIF($B$6:$B$162,B14,$E$6:$E$162) -> 30 | G14: B | H14: =IFERROR(VLOOKUP(G14,Tarif_Plan!$B$5:$G$10,6,FALSE()),"Kelas tdk ditemukan") -> 1000000 | I14: =IF(F14=0,0,E14/F14) -> 0 | J14: =ROUND(I14*H14,0) -> 0 | K14: =IF(COUNTIF($B$6:B14,B14)=COUNTIF($B$6:$B$162,B14),1,0) -> 1 | L14: =SUMIF($B$6:$B$162,B14,$J$6:$J$162) -> 1000000 | M14: =H14-L14 -> 0 | N14: =IF(F14=0,0,J14+IF(K14=1,M14,0)) -> 0 | O14: =IF(F14=0,"POIN 0 - PERLU KEPUTUSAN MANUAL","OK") -> OK
B15: Engagement of Keelie & Gamma | C15: Nehemia Lantis Jojo Winarjati | D15: Jumpback | E15: 0 | F15: =SUMIF($B$6:$B$162,B15,$E$6:$E$162) -> 17 | G15: B | H15: =IFERROR(VLOOKUP(G15,Tarif_Plan!$B$5:$G$10,6,FALSE()),"Kelas tdk ditemukan") -> 1000000 | I15: =IF(F15=0,0,E15/F15) -> 0 | J15: =ROUND(I15*H15,0) -> 0 | K15: =IF(COUNTIF($B$6:B15,B15)=COUNTIF($B$6:$B$162,B15),1,0) -> 0 | L15: =SUMIF($B$6:$B$162,B15,$J$6:$J$162) -> 1000002 | M15: =H15-L15 -> -2 | N15: =IF(F15=0,0,J15+IF(K15=1,M15,0)) -> 0 | O15: =IF(F15=0,"POIN 0 - PERLU KEPUTUSAN MANUAL","OK") -> OK
B16: Engagement of Keelie & Gamma | C16: Yoga Pratama Abdi Margo | D16: Compose | E16: 3 | F16: =SUMIF($B$6:$B$162,B16,$E$6:$E$162) -> 17 | G16: B | H16: =IFERROR(VLOOKUP(G16,Tarif_Plan!$B$5:$G$10,6,FALSE()),"Kelas tdk ditemukan") -> 1000000 | I16: =IF(F16=0,0,E16/F16) -> 0.17647059 | J16: =ROUND(I16*H16,0) -> 176471 | K16: =IF(COUNTIF($B$6:B16,B16)=COUNTIF($B$6:$B$162,B16),1,0) -> 0 | L16: =SUMIF($B$6:$B$162,B16,$J$6:$J$162) -> 1000002 | M16: =H16-L16 -> -2 | N16: =IF(F16=0,0,J16+IF(K16=1,M16,0)) -> 176471 | O16: =IF(F16=0,"POIN 0 - PERLU KEPUTUSAN MANUAL","OK") -> OK
B17: Engagement of Keelie & Gamma | C17: David Firdaus | D17: Generalist (All in One) | E17: 3 | F17: =SUMIF($B$6:$B$162,B17,$E$6:$E$162) -> 17 | G17: B | H17: =IFERROR(VLOOKUP(G17,Tarif_Plan!$B$5:$G$10,6,FALSE()),"Kelas tdk ditemukan") -> 1000000 | I17: =IF(F17=0,0,E17/F17) -> 0.17647059 | J17: =ROUND(I17*H17,0) -> 176471 | K17: =IF(COUNTIF($B$6:B17,B17)=COUNTIF($B$6:$B$162,B17),1,0) -> 0 | L17: =SUMIF($B$6:$B$162,B17,$J$6:$J$162) -> 1000002 | M17: =H17-L17 -> -2 | N17: =IF(F17=0,0,J17+IF(K17=1,M17,0)) -> 176471 | O17: =IF(F17=0,"POIN 0 - PERLU KEPUTUSAN MANUAL","OK") -> OK
... B66: Kayren Lie Sasongko 17th Birthday | C66: Hutomo Putra Winata | D66: Jumpback | E66: 0 | F66: =SUMIF($B$6:$B$162,B66,$E$6:$E$162) -> 35 | G66: B | H66: =IFERROR(VLOOKUP(G66,Tarif_Plan!$B$5:$G$10,6,FALSE()),"Kelas tdk ditemukan") -> 1000000 | I66: =IF(F66=0,0,E66/F66) -> 0 | J66: =ROUND(I66*H66,0) -> 0 | K66: =IF(COUNTIF($B$6:B66,B66)=COUNTIF($B$6:$B$162,B66),1,0) -> 0 | L66: =SUMIF($B$6:$B$162,B66,$J$6:$J$162) -> 999999 | M66: =H66-L66 -> 1 | N66: =IF(F66=0,0,J66+IF(K66=1,M66,0)) -> 0 | O66: =IF(F66=0,"POIN 0 - PERLU KEPUTUSAN MANUAL","OK") -> OK
B67: Kayren Lie Sasongko 17th Birthday | C67: Yumna Syarifah | E67: 1 | F67: =SUMIF($B$6:$B$162,B67,$E$6:$E$162) -> 35 | G67: B | H67: =IFERROR(VLOOKUP(G67,Tarif_Plan!$B$5:$G$10,6,FALSE()),"Kelas tdk ditemukan") -> 1000000 | I67: =IF(F67=0,0,E67/F67) -> 0.028571429 | J67: =ROUND(I67*H67,0) -> 28571 | K67: =IF(COUNTIF($B$6:B67,B67)=COUNTIF($B$6:$B$162,B67),1,0) -> 0 | L67: =SUMIF($B$6:$B$162,B67,$J$6:$J$162) -> 999999 | M67: =H67-L67 -> 1 | N67: =IF(F67=0,0,J67+IF(K67=1,M67,0)) -> 28571 | O67: =IF(F67=0,"POIN 0 - PERLU KEPUTUSAN MANUAL","OK") -> OK
B68: Kayren Lie Sasongko 17th Birthday | C68: Muhammad Zainul Ma'arif | E68: 2 | F68: =SUMIF($B$6:$B$162,B68,$E$6:$E$162) -> 35 | G68: B | H68: =IFERROR(VLOOKUP(G68,Tarif_Plan!$B$5:$G$10,6,FALSE()),"Kelas tdk ditemukan") -> 1000000 | I68: =IF(F68=0,0,E68/F68) -> 0.057142857 | J68: =ROUND(I68*H68,0) -> 57143 | K68: =IF(COUNTIF($B$6:B68,B68)=COUNTIF($B$6:$B$162,B68),1,0) -> 1 | L68: =SUMIF($B$6:$B$162,B68,$J$6:$J$162) -> 999999 | M68: =H68-L68 -> 1 | N68: =IF(F68=0,0,J68+IF(K68=1,M68,0)) -> 57144 | O68: =IF(F68=0,"POIN 0 - PERLU KEPUTUSAN MANUAL","OK") -> OK
B69: Devin & Michelle | C69: Ariya Putra Sundava | D69: Jumpback | E69: 0 | F69: =SUMIF($B$6:$B$162,B69,$E$6:$E$162) -> 22 | G69: B | H69: =IFERROR(VLOOKUP(G69,Tarif_Plan!$B$5:$G$10,6,FALSE()),"Kelas tdk ditemukan") -> 1000000 | I69: =IF(F69=0,0,E69/F69) -> 0 | J69: =ROUND(I69*H69,0) -> 0 | K69: =IF(COUNTIF($B$6:B69,B69)=COUNTIF($B$6:$B$162,B69),1,0) -> 0 | L69: =SUMIF($B$6:$B$162,B69,$J$6:$J$162) -> 1000000 | M69: =H69-L69 -> 0 | N69: =IF(F69=0,0,J69+IF(K69=1,M69,0)) -> 0 | O69: =IF(F69=0,"POIN 0 - PERLU KEPUTUSAN MANUAL","OK") -> OK
B70: Devin & Michelle | C70: Yoga Pratama Abdi Margo | D70: Compose | E70: 3 | F70: =SUMIF($B$6:$B$162,B70,$E$6:$E$162) -> 22 | G70: B | H70: =IFERROR(VLOOKUP(G70,Tarif_Plan!$B$5:$G$10,6,FALSE()),"Kelas tdk ditemukan") -> 1000000 | I70: =IF(F70=0,0,E70/F70) -> 0.13636364 | J70: =ROUND(I70*H70,0) -> 136364 | K70: =IF(COUNTIF($B$6:B70,B70)=COUNTIF($B$6:$B$162,B70),1,0) -> 0 | L70: =SUMIF($B$6:$B$162,B70,$J$6:$J$162) -> 1000000 | M70: =H70-L70 -> 0 | N70: =IF(F70=0,0,J70+IF(K70=1,M70,0)) -> 136364 | O70: =IF(F70=0,"POIN 0 - PERLU KEPUTUSAN MANUAL","OK") -> OK
B71: Devin & Michelle | C71: David Firdaus | D71: Generalist (All in One) | E71: 4 | F71: =SUMIF($B$6:$B$162,B71,$E$6:$E$162) -> 22 | G71: B | H71: =IFERROR(VLOOKUP(G71,Tarif_Plan!$B$5:$G$10,6,FALSE()),"Kelas tdk ditemukan") -> 1000000 | I71: =IF(F71=0,0,E71/F71) -> 0.18181818 | J71: =ROUND(I71*H71,0) -> 181818 | K71: =IF(COUNTIF($B$6:B71,B71)=COUNTIF($B$6:$B$162,B71),1,0) -> 0 | L71: =SUMIF($B$6:$B$162,B71,$J$6:$J$162) -> 1000000 | M71: =H71-L71 -> 0 | N71: =IF(F71=0,0,J71+IF(K71=1,M71,0)) -> 181818 | O71: =IF(F71=0,"POIN 0 - PERLU KEPUTUSAN MANUAL","OK") -> OK
B72: Devin & Michelle | C72: Danny Dwi Prasetya | D72: Generalist (All in One) | E72: 5 | F72: =SUMIF($B$6:$B$162,B72,$E$6:$E$162) -> 22 | G72: B | H72: =IFERROR(VLOOKUP(G72,Tarif_Plan!$B$5:$G$10,6,FALSE()),"Kelas tdk ditemukan") -> 1000000 | I72: =IF(F72=0,0,E72/F72) -> 0.22727273 | J72: =ROUND(I72*H72,0) -> 227273 | K72: =IF(COUNTIF($B$6:B72,B72)=COUNTIF($B$6:$B$162,B72),1,0) -> 0 | L72: =SUMIF($B$6:$B$162,B72,$J$6:$J$162) -> 1000000 | M72: =H72-L72 -> 0 | N72: =IF(F72=0,0,J72+IF(K72=1,M72,0)) -> 227273 | O72: =IF(F72=0,"POIN 0 - PERLU KEPUTUSAN MANUAL","OK") -> OK
B73: Devin & Michelle | C73: Aurellyn Briza | D73: Generalist (All in One) | E73: 2 | F73: =SUMIF($B$6:$B$162,B73,$E$6:$E$162) -> 22 | G73: B | H73: =IFERROR(VLOOKUP(G73,Tarif_Plan!$B$5:$G$10,6,FALSE()),"Kelas tdk ditemukan") -> 1000000 | I73: =IF(F73=0,0,E73/F73) -> 0.090909091 | J73: =ROUND(I73*H73,0) -> 90909 | K73: =IF(COUNTIF($B$6:B73,B73)=COUNTIF($B$6:$B$162,B73),1,0) -> 0 | L73: =SUMIF($B$6:$B$162,B73,$J$6:$J$162) -> 1000000 | M73: =H73-L73 -> 0 | N73: =IF(F73=0,0,J73+IF(K73=1,M73,0)) -> 90909 | O73: =IF(F73=0,"POIN 0 - PERLU KEPUTUSAN MANUAL","OK") -> OK
B74: Devin & Michelle | C74: Sucha Aji Nugroho | D74: Animator | E74: 4 | F74: =SUMIF($B$6:$B$162,B74,$E$6:$E$162) -> 22 | G74: B | H74: =IFERROR(VLOOKUP(G74,Tarif_Plan!$B$5:$G$10,6,FALSE()),"Kelas tdk ditemukan") -> 1000000 | I74: =IF(F74=0,0,E74/F74) -> 0.18181818 | J74: =ROUND(I74*H74,0) -> 181818 | K74: =IF(COUNTIF($B$6:B74,B74)=COUNTIF($B$6:$B$162,B74),1,0) -> 0 | L74: =SUMIF($B$6:$B$162,B74,$J$6:$J$162) -> 1000000 | M74: =H74-L74 -> 0 | N74: =IF(F74=0,0,J74+IF(K74=1,M74,0)) -> 181818 | O74: =IF(F74=0,"POIN 0 - PERLU KEPUTUSAN MANUAL","OK") -> OK
B75: Devin & Michelle | C75: Rani Claudia Bitjoli | D75: Animator | E75: 4 | F75: =SUMIF($B$6:$B$162,B75,$E$6:$E$162) -> 22 | G75: B | H75: =IFERROR(VLOOKUP(G75,Tarif_Plan!$B$5:$G$10,6,FALSE()),"Kelas tdk ditemukan") -> 1000000 | I75: =IF(F75=0,0,E75/F75) -> 0.18181818 | J75: =ROUND(I75*H75,0) -> 181818 | K75: =IF(COUNTIF($B$6:B75,B75)=COUNTIF($B$6:$B$162,B75),1,0) -> 0 | L75: =SUMIF($B$6:$B$162,B75,$J$6:$J$162) -> 1000000 | M75: =H75-L75 -> 0 | N75: =IF(F75=0,0,J75+IF(K75=1,M75,0)) -> 181818 | O75: =IF(F75=0,"POIN 0 - PERLU KEPUTUSAN MANUAL","OK") -> OK
B76: Devin & Michelle | C76: Ariya Putra Sundava | D76: Jumpback | E76: 0 | F76: =SUMIF($B$6:$B$162,B76,$E$6:$E$162) -> 22 | G76: B | H76: =IFERROR(VLOOKUP(G76,Tarif_Plan!$B$5:$G$10,6,FALSE()),"Kelas tdk ditemukan") -> 1000000 | I76: =IF(F76=0,0,E76/F76) -> 0 | J76: =ROUND(I76*H76,0) -> 0 | K76: =IF(COUNTIF($B$6:B76,B76)=COUNTIF($B$6:$B$162,B76),1,0) -> 1 | L76: =SUMIF($B$6:$B$162,B76,$J$6:$J$162) -> 1000000 | M76: =H76-L76 -> 0 | N76: =IF(F76=0,0,J76+IF(K76=1,M76,0)) -> 0 | O76: =IF(F76=0,"POIN 0 - PERLU KEPUTUSAN MANUAL","OK") -> OK
B77: David & Celine | C77: Fuad Ashari | D77: Compose | E77: 4 | F77: =SUMIF($B$6:$B$162,B77,$E$6:$E$162) -> 12 | G77: B | H77: =IFERROR(VLOOKUP(G77,Tarif_Plan!$B$5:$G$10,6,FALSE()),"Kelas tdk ditemukan") -> 1000000 | I77: =IF(F77=0,0,E77/F77) -> 0.33333333 | J77: =ROUND(I77*H77,0) -> 333333 | K77: =IF(COUNTIF($B$6:B77,B77)=COUNTIF($B$6:$B$162,B77),1,0) -> 0 | L77: =SUMIF($B$6:$B$162,B77,$J$6:$J$162) -> 999999 | M77: =H77-L77 -> 1 | N77: =IF(F77=0,0,J77+IF(K77=1,M77,0)) -> 333333 | O77: =IF(F77=0,"POIN 0 - PERLU KEPUTUSAN MANUAL","OK") -> OK
B78: David & Celine | C78: Indra Setya Himawan | D78: Generalist (All in One) | E78: 4 | F78: =SUMIF($B$6:$B$162,B78,$E$6:$E$162) -> 12 | G78: B | H78: =IFERROR(VLOOKUP(G78,Tarif_Plan!$B$5:$G$10,6,FALSE()),"Kelas tdk ditemukan") -> 1000000 | I78: =IF(F78=0,0,E78/F78) -> 0.33333333 | J78: =ROUND(I78*H78,0) -> 333333 | K78: =IF(COUNTIF($B$6:B78,B78)=COUNTIF($B$6:$B$162,B78),1,0) -> 0 | L78: =SUMIF($B$6:$B$162,B78,$J$6:$J$162) -> 999999 | M78: =H78-L78 -> 1 | N78: =IF(F78=0,0,J78+IF(K78=1,M78,0)) -> 333333 | O78: =IF(F78=0,"POIN 0 - PERLU KEPUTUSAN MANUAL","OK") -> OK
B79: David & Celine | C79: Fajar Ramadhan | D79: Generalist (All in One) | E79: 4 | F79: =SUMIF($B$6:$B$162,B79,$E$6:$E$162) -> 12 | G79: B | H79: =IFERROR(VLOOKUP(G79,Tarif_Plan!$B$5:$G$10,6,FALSE()),"Kelas tdk ditemukan") -> 1000000 | I79: =IF(F79=0,0,E79/F79) -> 0.33333333 | J79: =ROUND(I79*H79,0) -> 333333 | K79: =IF(COUNTIF($B$6:B79,B79)=COUNTIF($B$6:$B$162,B79),1,0) -> 1 | L79: =SUMIF($B$6:$B$162,B79,$J$6:$J$162) -> 999999 | M79: =H79-L79 -> 1 | N79: =IF(F79=0,0,J79+IF(K79=1,M79,0)) -> 333334 | O79: =IF(F79=0,"POIN 0 - PERLU KEPUTUSAN MANUAL","OK") -> OK
B80: Ms. Sukma Birthday | C80: Yumna Syarifah | E80: 4 | F80: =SUMIF($B$6:$B$162,B80,$E$6:$E$162) -> 9 | G80: B | H80: =IFERROR(VLOOKUP(G80,Tarif_Plan!$B$5:$G$10,6,FALSE()),"Kelas tdk ditemukan") -> 1000000 | I80: =IF(F80=0,0,E80/F80) -> 0.44444444 | J80: =ROUND(I80*H80,0) -> 444444 | K80: =IF(COUNTIF($B$6:B80,B80)=COUNTIF($B$6:$B$162,B80),1,0) -> 0 | L80: =SUMIF($B$6:$B$162,B80,$J$6:$J$162) -> 999999 | M80: =H80-L80 -> 1 | N80: =IF(F80=0,0,J80+IF(K80=1,M80,0)) -> 444444 | O80: =IF(F80=0,"POIN 0 - PERLU KEPUTUSAN MANUAL","OK") -> OK
B81: Ms. Sukma Birthday | C81: Fahrul Hidayat | E81: 2 | F81: =SUMIF($B$6:$B$162,B81,$E$6:$E$162) -> 9 | G81: B | H81: =IFERROR(VLOOKUP(G81,Tarif_Plan!$B$5:$G$10,6,FALSE()),"Kelas tdk ditemukan") -> 1000000 | I81: =IF(F81=0,0,E81/F81) -> 0.22222222 | J81: =ROUND(I81*H81,0) -> 222222 | K81: =IF(COUNTIF($B$6:B81,B81)=COUNTIF($B$6:$B$162,B81),1,0) -> 0 | L81: =SUMIF($B$6:$B$162,B81,$J$6:$J$162) -> 999999 | M81: =H81-L81 -> 1 | N81: =IF(F81=0,0,J81+IF(K81=1,M81,0)) -> 222222 | O81: =IF(F81=0,"POIN 0 - PERLU KEPUTUSAN MANUAL","OK") -> OK
B82: Ms. Sukma Birthday | C82: Muhammad Zainul Ma'arif | E82: 3 | F82: =SUMIF($B$6:$B$162,B82,$E$6:$E$162) -> 9 | G82: B | H82: =IFERROR(VLOOKUP(G82,Tarif_Plan!$B$5:$G$10,6,FALSE()),"Kelas tdk ditemukan") -> 1000000 | I82: =IF(F82=0,0,E82/F82) -> 0.33333333 | J82: =ROUND(I82*H82,0) -> 333333 | K82: =IF(COUNTIF($B$6:B82,B82)=COUNTIF($B$6:$B$162,B82),1,0) -> 1 | L82: =SUMIF($B$6:$B$162,B82,$J$6:$J$162) -> 999999 | M82: =H82-L82 -> 1 | N82: =IF(F82=0,0,J82+IF(K82=1,M82,0)) -> 333334 | O82: =IF(F82=0,"POIN 0 - PERLU KEPUTUSAN MANUAL","OK") -> OK
B83: Caroline Birthday | C83: Yumna Syarifah | E83: 4 | F83: =SUMIF($B$6:$B$162,B83,$E$6:$E$162) -> 12 | G83: B | H83: =IFERROR(VLOOKUP(G83,Tarif_Plan!$B$5:$G$10,6,FALSE()),"Kelas tdk ditemukan") -> 1000000 | I83: =IF(F83=0,0,E83/F83) -> 0.33333333 | J83: =ROUND(I83*H83,0) -> 333333 | K83: =IF(COUNTIF($B$6:B83,B83)=COUNTIF($B$6:$B$162,B83),1,0) -> 0 | L83: =SUMIF($B$6:$B$162,B83,$J$6:$J$162) -> 999999 | M83: =H83-L83 -> 1 | N83: =IF(F83=0,0,J83+IF(K83=1,M83,0)) -> 333333 | O83: =IF(F83=0,"POIN 0 - PERLU KEPUTUSAN MANUAL","OK") -> OK
B84: Caroline Birthday | C84: Fahrul Hidayat | E84: 4 | F84: =SUMIF($B$6:$B$162,B84,$E$6:$E$162) -> 12 | G84: B | H84: =IFERROR(VLOOKUP(G84,Tarif_Plan!$B$5:$G$10,6,FALSE()),"Kelas tdk ditemukan") -> 1000000 | I84: =IF(F84=0,0,E84/F84) -> 0.33333333 | J84: =ROUND(I84*H84,0) -> 333333 | K84: =IF(COUNTIF($B$6:B84,B84)=COUNTIF($B$6:$B$162,B84),1,0) -> 0 | L84: =SUMIF($B$6:$B$162,B84,$J$6:$J$162) -> 999999 | M84: =H84-L84 -> 1 | N84: =IF(F84=0,0,J84+IF(K84=1,M84,0)) -> 333333 | O84: =IF(F84=0,"POIN 0 - PERLU KEPUTUSAN MANUAL","OK") -> OK
B85: Caroline Birthday | C85: Muhammad Zainul Ma'arif | E85: 4 | F85: =SUMIF($B$6:$B$162,B85,$E$6:$E$162) -> 12 | G85: B | H85: =IFERROR(VLOOKUP(G85,Tarif_Plan!$B$5:$G$10,6,FALSE()),"Kelas tdk ditemukan") -> 1000000 | I85: =IF(F85=0,0,E85/F85) -> 0.33333333 | J85: =ROUND(I85*H85,0) -> 333333 | K85: =IF(COUNTIF($B$6:B85,B85)=COUNTIF($B$6:$B$162,B85),1,0) -> 1 | L85: =SUMIF($B$6:$B$162,B85,$J$6:$J$162) -> 999999 | M85: =H85-L85 -> 1 | N85: =IF(F85=0,0,J85+IF(K85=1,M85,0)) -> 333334 | O85: =IF(F85=0,"POIN 0 - PERLU KEPUTUSAN MANUAL","OK") -> OK
B86: Kate 2nd Birthday | C86: Yumna Syarifah | E86: 8 | F86: =SUMIF($B$6:$B$162,B86,$E$6:$E$162) -> 20 | G86: B | H86: =IFERROR(VLOOKUP(G86,Tarif_Plan!$B$5:$G$10,6,FALSE()),"Kelas tdk ditemukan") -> 1000000 | I86: =IF(F86=0,0,E86/F86) -> 0.4 | J86: =ROUND(I86*H86,0) -> 400000 | K86: =IF(COUNTIF($B$6:B86,B86)=COUNTIF($B$6:$B$162,B86),1,0) -> 0 | L86: =SUMIF($B$6:$B$162,B86,$J$6:$J$162) -> 1000000 | M86: =H86-L86 -> 0 | N86: =IF(F86=0,0,J86+IF(K86=1,M86,0)) -> 400000 | O86: =IF(F86=0,"POIN 0 - PERLU KEPUTUSAN MANUAL","OK") -> OK
B87: Kate 2nd Birthday | C87: Fahrul Hidayat | E87: 6 | F87: =SUMIF($B$6:$B$162,B87,$E$6:$E$162) -> 20 | G87: B | H87: =IFERROR(VLOOKUP(G87,Tarif_Plan!$B$5:$G$10,6,FALSE()),"Kelas tdk ditemukan") -> 1000000 | I87: =IF(F87=0,0,E87/F87) -> 0.3 | J87: =ROUND(I87*H87,0) -> 300000 | K87: =IF(COUNTIF($B$6:B87,B87)=COUNTIF($B$6:$B$162,B87),1,0) -> 0 | L87: =SUMIF($B$6:$B$162,B87,$J$6:$J$162) -> 1000000 | M87: =H87-L87 -> 0 | N87: =IF(F87=0,0,J87+IF(K87=1,M87,0)) -> 300000 | O87: =IF(F87=0,"POIN 0 - PERLU KEPUTUSAN MANUAL","OK") -> OK
B88: Kate 2nd Birthday | C88: Muhammad Zainul Ma'arif | E88: 6 | F88: =SUMIF($B$6:$B$162,B88,$E$6:$E$162) -> 20 | G88: B | H88: =IFERROR(VLOOKUP(G88,Tarif_Plan!$B$5:$G$10,6,FALSE()),"Kelas tdk ditemukan") -> 1000000 | I88: =IF(F88=0,0,E88/F88) -> 0.3 | J88: =ROUND(I88*H88,0) -> 300000 | K88: =IF(COUNTIF($B$6:B88,B88)=COUNTIF($B$6:$B$162,B88),1,0) -> 1 | L88: =SUMIF($B$6:$B$162,B88,$J$6:$J$162) -> 1000000 | M88: =H88-L88 -> 0 | N88: =IF(F88=0,0,J88+IF(K88=1,M88,0)) -> 300000 | O88: =IF(F88=0,"POIN 0 - PERLU KEPUTUSAN MANUAL","OK") -> OK
B89: Pena Saya - St Yakobus | C89: Gilang Rizky Al Mizan | D89: Animator - Production | E89: 4 | F89: =SUMIF($B$6:$B$162,B89,$E$6:$E$162) -> 4 | G89: B | H89: =IFERROR(VLOOKUP(G89,Tarif_Plan!$B$5:$G$10,6,FALSE()),"Kelas tdk ditemukan") -> 1000000 | I89: =IF(F89=0,0,E89/F89) -> 1 | J89: =ROUND(I89*H89,0) -> 1000000 | K89: =IF(COUNTIF($B$6:B89,B89)=COUNTIF($B$6:$B$162,B89),1,0) -> 1 | L89: =SUMIF($B$6:$B$162,B89,$J$6:$J$162) -> 1000000 | M89: =H89-L89 -> 0 | N89: =IF(F89=0,0,J89+IF(K89=1,M89,0)) -> 1000000 | O89: =IF(F89=0,"POIN 0 - PERLU KEPUTUSAN MANUAL","OK") -> OK
B90: Reuni sekolah SMAK Santo Paulus Jember | C90: Riyadus Solihin | D90: Modeller | E90: 1 | F90: =SUMIF($B$6:$B$162,B90,$E$6:$E$162) -> 30 | G90: B | H90: =IFERROR(VLOOKUP(G90,Tarif_Plan!$B$5:$G$10,6,FALSE()),"Kelas tdk ditemukan") -> 1000000 | I90: =IF(F90=0,0,E90/F90) -> 0.033333333 | J90: =ROUND(I90*H90,0) -> 33333 | K90: =IF(COUNTIF($B$6:B90,B90)=COUNTIF($B$6:$B$162,B90),1,0) -> 0 | L90: =SUMIF($B$6:$B$162,B90,$J$6:$J$162) -> 999998 | M90: =H90-L90 -> 2 | N90: =IF(F90=0,0,J90+IF(K90=1,M90,0)) -> 33333 | O90: =IF(F90=0,"POIN 0 - PERLU KEPUTUSAN MANUAL","OK") -> OK
B91: Reuni sekolah SMAK Santo Paulus Jember | C91: Vicky Apriyana Firdaus | D91: Modeller | E91: 1 | F91: =SUMIF($B$6:$B$162,B91,$E$6:$E$162) -> 30 | G91: B | H91: =IFERROR(VLOOKUP(G91,Tarif_Plan!$B$5:$G$10,6,FALSE()),"Kelas tdk ditemukan") -> 1000000 | I91: =IF(F91=0,0,E91/F91) -> 0.033333333 | J91: =ROUND(I91*H91,0) -> 33333 | K91: =IF(COUNTIF($B$6:B91,B91)=COUNTIF($B$6:$B$162,B91),1,0) -> 0 | L91: =SUMIF($B$6:$B$162,B91,$J$6:$J$162) -> 999998 | M91: =H91-L91 -> 2 | N91: =IF(F91=0,0,J91+IF(K91=1,M91,0)) -> 33333 | O91: =IF(F91=0,"POIN 0 - PERLU KEPUTUSAN MANUAL","OK") -> OK
...
